<?xml version="1.0" ?>
<!--This file contains the SDF model of a KUKA iiwa robot with a wsg50 gripper.
    It has been produced from the varients in //third_party/robotics/models.
    Note:  This file is temporary, and should be deleted once Bullet supports
    importing models in SDF.  Also, this file has been specialized for Bullet,
    because the mass of the base link has been set to 0, as needed by Bullet.
    Note:  All of the gripper link poses have been adjusted in the z direction
    to achieve a reasonable position of the gripper relative to the arm.
    Note: The joint names for the KUKA have been changed to J0, J1, etc. -->
    <!--There is problem with the kuka mesh and everytime i use it gazebo crashes so I am gonna comment that part-->


<robot name="test_robot">


    <!-- forearm and palm -->

    <link name="forearm">
        <origin xyz="0 0 0.09" rpy="0 0 0"/>
        
        <inertial>
            <origin xyz="0 0 0.09" rpy="0 0 0"/>
            <mass value="1.8"/>
            <inertia 
                ixx="0.108" 
                ixy="0" 
                ixz="0" 
                iyy="0.108" 
                iyz="0" 
                izz="0.054"
            />
        </inertial>

        <visual>
            <origin xyz="0 0 0" rpy="0 0 1.57079632679"/>
            <geometry name="visual_forearm_link">
                <mesh filename="/meshes/forearm_lite.dae" scale="1.0 1.0 1.0"/>
            </geometry>
            <material name = "forearm_color">
                <color rgba="0.6 1 0.5 1"/>
            </material>
        </visual>

        <collision>
            <origin xyz="0 0 0" rpy="0 0 1.57079632679"/>
            <geometry name="collision_forearm_link">
                <mesh filename="/meshes/forearm_lite.dae" scale="1.0 1.0 1.0"/>
            </geometry>
            <material name="Grey"/>
        </collision>
    </link>


    <link name="palm">
        <origin xyz="0 0 0" rpy="0 0 0"/>
        
        <inertial>
            <origin xyz="0 0 0.035" rpy="0 0 0"/>
            <mass value="0.3"/>
            <inertia 
                ixx="0.0003581" 
                ixy="0" 
                ixz="0" 
                iyy="0.0005287" 
                iyz="0" 
                izz="0.000191"
            />
        </inertial>

        <visual>
            <origin xyz="0 0 0" rpy="0 0 0"/>
            <geometry name="visual_palm_link">
                <mesh filename="/meshes/palm2.dae" scale="-0.001 0.001 0.001"/>
            </geometry>
            <material name = "palm_color">
                <color rgba="0.8 0.4 0 1"/>
            </material>
        </visual>

        <collision>
            <origin xyz="0 0 0" rpy="0 0 0"/>
            <geometry name="collision_palm_link">
                <mesh filename="/meshes/palm2_c.dae" scale="0.001 0.001 0.001"/>
            </geometry>
            <material name="Grey"/>
        </collision>
    </link>

    <joint name="palm_forearm" type="fixed">
        <parent link="forearm"/>
        <child  link="palm"/>
        <origin xyz="0 -0.015 0.149" rpy="-0.698131700798 0 0"/>
        <axis xyz="0 -1 0"/>
    </joint>

    <!-- fingers  -->
    
        
            <link name="knuckle_FF">
                <origin xyz="0 0 0" rpy="0 0 0"/>

                <inertial>
                    <origin xyz="0 0 0" rpy="0 0 0"/>
                    <mass value="0.008"/>
                    <inertia 
                        ixx="2.6e-07" 
                        ixy="0" 
                        ixz="0" 
                        iyy="2.6e-07" 
                        iyz="0" 
                        izz="3.2e-07"
                    />
                </inertial>

                <visual>
                    <origin xyz="0 0 0.0005" rpy="0 0 0"/>
                    <geometry name="visual_knuckle_link">
                        <mesh filename="/meshes/knuckle.dae" scale="0.001 0.001 0.001"/>
                    </geometry>
                    <material name = "knuckle_FF_color">
                        <color rgba="0.6 1 0.5 1"/>
                    </material>
                </visual>

                <collision>
                    <origin xyz="0 0 0.0005" rpy="0 0 0"/>
                    <geometry name="collision_knuckle_link">
                        <mesh filename="/meshes/knuckle.dae" scale="0.001 0.001 0.001"/>
                    </geometry>
                    <material name="Grey"/>
                </collision>
            </link>

            <joint name="J4_FF" type="revolute">
                <parent link="palm"/>
                <child link ="knuckle_FF"/>

                <origin xyz="-0.033 0 0.095" rpy="0 0 0"/>
                <axis xyz="0 0.766044 -0.642788"/>
                <limit  effort="2.0" 
                        lower="-0.349066" 
                        upper="0.349066" 
                        velocity="2.0" />
                <dynamics damping="0.1"/>
            </joint>
        
            <link name="proximal_FF">
                <origin xyz="0 0 0" rpy="0 0 0"/>

                <inertial>
                    <origin xyz="0 0 0.0225" rpy="0 0 0"/>
                    <mass value="0.03"/>
                    <inertia 
                        ixx="9.8e-06" 
                        ixy="0" 
                        ixz="0" 
                        iyy="1.0e-05" 
                        iyz="0" 
                        izz="1.8e-06"
                    />
                </inertial>

                <visual>
                    <origin xyz="0 0 0" rpy="0 0 0"/>
                    <geometry name="visual_knuckle_link">
                        <mesh filename="/meshes/F3.dae" scale="0.001 0.001 0.001"/>
                    </geometry>
                    <material name = "proximal_FF_color">
                        <color rgba="0.7 1 1 1"/>
                    </material>
                </visual>

                <collision>
                    <origin xyz="0 0 0" rpy="0 0 0"/>
                    <geometry name="collision_knuckle_link">
                        <mesh filename="/meshes/F3_c.dae" scale="0.001 0.001 0.001"/>
                    </geometry>
                    <material name="Grey"/>
                </collision>
            </link>

            <joint name="J3_FF" type="revolute">
                <parent link="knuckle_FF"/>
                <child link ="proximal_FF"/>

                <origin xyz="0 0 0" rpy="0 0 0"/>
                <axis xyz="1 0 0"/>
                <limit  effort="2.0" 
                        lower="0" 
                        upper="1.5708" 
                        velocity="2.0" />
                <dynamics damping="0.1"/>
            </joint>
        
            <link name="middle_FF">
                <origin xyz="0 0 0" rpy="0 0 0"/>

                <inertial>
                    <origin xyz="0 0 0.0125" rpy="0 0 0"/>
                    <mass value="0.017"/>
                    <inertia 
                        ixx="2.6e-06" 
                        ixy="0" 
                        ixz="0" 
                        iyy="2.7e-06" 
                        iyz="0" 
                        izz="8.7e-07"
                    />
                </inertial>

                <visual>
                    <origin xyz="0 0 0" rpy="0 0 0"/>
                    <geometry name="visual_knuckle_link">
                        <mesh filename="/meshes/F2.dae" scale="0.001 0.001 0.001"/>
                    </geometry>
                    <material name = "middle_FF_color">
                        <color rgba="0.8 0.3 0.6 1"/>
                    </material>
                </visual>

                <collision>
                    <origin xyz="0 0 0" rpy="0 0 0"/>
                    <geometry name="collision_knuckle_link">
                        <mesh filename="/meshes/F2_c.dae" scale="0.001 0.001 0.001"/>
                    </geometry>
                    <material name="Grey"/>
                </collision>
            </link>

            <joint name="J2_FF" type="revolute">
                <parent link="proximal_FF"/>
                <child link ="middle_FF"/>

                <origin xyz="0 0 0.045" rpy="0 0 0"/>
                <axis xyz="1 0 0"/>
                <limit  effort="2.0" 
                        lower="0" 
                        upper="1.5708" 
                        velocity="2.0" />
                <dynamics damping="0.1"/>
            </joint>
        
            <link name="distal_FF">
                <origin xyz="0 0 0" rpy="0 0 0"/>

                <inertial>
                    <origin xyz="0 0 0.012" rpy="0 0 0"/>
                    <mass value="0.012"/>
                    <inertia 
                        ixx="9.4e-07" 
                        ixy="0" 
                        ixz="0" 
                        iyy="1.1e-06" 
                        iyz="0" 
                        izz="5.3e-07"
                    />
                </inertial>

                <visual>
                    <origin xyz="0 0 0" rpy="0 0 0"/>
                    <geometry name="visual_knuckle_link">
                        <mesh filename="/meshes/digit.STL" scale="1 1 1"/>
                    </geometry>
                    <material name = "distal_FF_color">
                        <color rgba="1 1 1 1"/>
                    </material>
                </visual>

                <collision>
                    <origin xyz="0 0 0" rpy="0 0 0"/>
                    <geometry name="collision_knuckle_link">
                        <mesh filename="/meshes/digit.STL" scale="1 1 1"/>
                    </geometry>
                    <material name="Grey"/>
                </collision>
            </link>

            <joint name="J1_FF" type="revolute">
                <parent link="middle_FF"/>
                <child link ="distal_FF"/>

                <origin xyz="0 0 0.025" rpy="0 0 -1.57"/>
                <axis xyz="0 1 0"/>
                <limit  effort="2.0" 
                        lower="0" 
                        upper="1.5708" 
                        velocity="2.0" />
                <dynamics damping="0.1"/>
            </joint>
        
    
        
            <link name="knuckle_MF">
                <origin xyz="0 0 0" rpy="0 0 0"/>

                <inertial>
                    <origin xyz="0 0 0" rpy="0 0 0"/>
                    <mass value="0.008"/>
                    <inertia 
                        ixx="2.6e-07" 
                        ixy="0" 
                        ixz="0" 
                        iyy="2.6e-07" 
                        iyz="0" 
                        izz="3.2e-07"
                    />
                </inertial>

                <visual>
                    <origin xyz="0 0 0.0005" rpy="0 0 0"/>
                    <geometry name="visual_knuckle_link">
                        <mesh filename="/meshes/knuckle.dae" scale="0.001 0.001 0.001"/>
                    </geometry>
                    <material name = "knuckle_MF_color">
                        <color rgba="0.6 1 0.5 1"/>
                    </material>
                </visual>

                <collision>
                    <origin xyz="0 0 0.0005" rpy="0 0 0"/>
                    <geometry name="collision_knuckle_link">
                        <mesh filename="/meshes/knuckle.dae" scale="0.001 0.001 0.001"/>
                    </geometry>
                    <material name="Grey"/>
                </collision>
            </link>

            <joint name="J4_MF" type="revolute">
                <parent link="palm"/>
                <child link ="knuckle_MF"/>

                <origin xyz="-0.011000000000000003 0.002536 0.098068" rpy="0 0 0"/>
                <axis xyz="0 0.766044 -0.642788"/>
                <limit  effort="2.0" 
                        lower="-0.349066" 
                        upper="0.349066" 
                        velocity="2.0" />
                <dynamics damping="0.1"/>
            </joint>
        
            <link name="proximal_MF">
                <origin xyz="0 0 0" rpy="0 0 0"/>

                <inertial>
                    <origin xyz="0 0 0.0225" rpy="0 0 0"/>
                    <mass value="0.03"/>
                    <inertia 
                        ixx="9.8e-06" 
                        ixy="0" 
                        ixz="0" 
                        iyy="1.0e-05" 
                        iyz="0" 
                        izz="1.8e-06"
                    />
                </inertial>

                <visual>
                    <origin xyz="0 0 0" rpy="0 0 0"/>
                    <geometry name="visual_knuckle_link">
                        <mesh filename="/meshes/F3.dae" scale="0.001 0.001 0.001"/>
                    </geometry>
                    <material name = "proximal_MF_color">
                        <color rgba="0.7 1 1 1"/>
                    </material>
                </visual>

                <collision>
                    <origin xyz="0 0 0" rpy="0 0 0"/>
                    <geometry name="collision_knuckle_link">
                        <mesh filename="/meshes/F3_c.dae" scale="0.001 0.001 0.001"/>
                    </geometry>
                    <material name="Grey"/>
                </collision>
            </link>

            <joint name="J3_MF" type="revolute">
                <parent link="knuckle_MF"/>
                <child link ="proximal_MF"/>

                <origin xyz="0 0 0" rpy="0 0 0"/>
                <axis xyz="1 0 0"/>
                <limit  effort="2.0" 
                        lower="0" 
                        upper="1.5708" 
                        velocity="2.0" />
                <dynamics damping="0.1"/>
            </joint>
        
            <link name="middle_MF">
                <origin xyz="0 0 0" rpy="0 0 0"/>

                <inertial>
                    <origin xyz="0 0 0.0125" rpy="0 0 0"/>
                    <mass value="0.017"/>
                    <inertia 
                        ixx="2.6e-06" 
                        ixy="0" 
                        ixz="0" 
                        iyy="2.7e-06" 
                        iyz="0" 
                        izz="8.7e-07"
                    />
                </inertial>

                <visual>
                    <origin xyz="0 0 0" rpy="0 0 0"/>
                    <geometry name="visual_knuckle_link">
                        <mesh filename="/meshes/F2.dae" scale="0.001 0.001 0.001"/>
                    </geometry>
                    <material name = "middle_MF_color">
                        <color rgba="0.8 0.3 0.6 1"/>
                    </material>
                </visual>

                <collision>
                    <origin xyz="0 0 0" rpy="0 0 0"/>
                    <geometry name="collision_knuckle_link">
                        <mesh filename="/meshes/F2_c.dae" scale="0.001 0.001 0.001"/>
                    </geometry>
                    <material name="Grey"/>
                </collision>
            </link>

            <joint name="J2_MF" type="revolute">
                <parent link="proximal_MF"/>
                <child link ="middle_MF"/>

                <origin xyz="0 0 0.045" rpy="0 0 0"/>
                <axis xyz="1 0 0"/>
                <limit  effort="2.0" 
                        lower="0" 
                        upper="1.5708" 
                        velocity="2.0" />
                <dynamics damping="0.1"/>
            </joint>
        
            <link name="distal_MF">
                <origin xyz="0 0 0" rpy="0 0 0"/>

                <inertial>
                    <origin xyz="0 0 0.012" rpy="0 0 0"/>
                    <mass value="0.012"/>
                    <inertia 
                        ixx="9.4e-07" 
                        ixy="0" 
                        ixz="0" 
                        iyy="1.1e-06" 
                        iyz="0" 
                        izz="5.3e-07"
                    />
                </inertial>

                <visual>
                    <origin xyz="0 0 0" rpy="0 0 0"/>
                    <geometry name="visual_knuckle_link">
                        <mesh filename="/meshes/digit.STL" scale="1 1 1"/>
                    </geometry>
                    <material name = "distal_MF_color">
                        <color rgba="1 1 1 1"/>
                    </material>
                </visual>

                <collision>
                    <origin xyz="0 0 0" rpy="0 0 0"/>
                    <geometry name="collision_knuckle_link">
                        <mesh filename="/meshes/digit.STL" scale="1 1 1"/>
                    </geometry>
                    <material name="Grey"/>
                </collision>
            </link>

            <joint name="J1_MF" type="revolute">
                <parent link="middle_MF"/>
                <child link ="distal_MF"/>

                <origin xyz="0 0 0.025" rpy="0 0 -1.57"/>
                <axis xyz="0 1 0"/>
                <limit  effort="2.0" 
                        lower="0" 
                        upper="1.5708" 
                        velocity="2.0" />
                <dynamics damping="0.1"/>
            </joint>
        
    
        
            <link name="knuckle_RF">
                <origin xyz="0 0 0" rpy="0 0 0"/>

                <inertial>
                    <origin xyz="0 0 0" rpy="0 0 0"/>
                    <mass value="0.008"/>
                    <inertia 
                        ixx="2.6e-07" 
                        ixy="0" 
                        ixz="0" 
                        iyy="2.6e-07" 
                        iyz="0" 
                        izz="3.2e-07"
                    />
                </inertial>

                <visual>
                    <origin xyz="0 0 0.0005" rpy="0 0 0"/>
                    <geometry name="visual_knuckle_link">
                        <mesh filename="/meshes/knuckle.dae" scale="0.001 0.001 0.001"/>
                    </geometry>
                    <material name = "knuckle_RF_color">
                        <color rgba="0.6 1 0.5 1"/>
                    </material>
                </visual>

                <collision>
                    <origin xyz="0 0 0.0005" rpy="0 0 0"/>
                    <geometry name="collision_knuckle_link">
                        <mesh filename="/meshes/knuckle.dae" scale="0.001 0.001 0.001"/>
                    </geometry>
                    <material name="Grey"/>
                </collision>
            </link>

            <joint name="J4_RF" type="revolute">
                <parent link="palm"/>
                <child link ="knuckle_RF"/>

                <origin xyz="0.010999999999999996 0 0.095" rpy="0 0 0"/>
                <axis xyz="0 0.766044 -0.642788"/>
                <limit  effort="2.0" 
                        lower="-0.349066" 
                        upper="0.349066" 
                        velocity="2.0" />
                <dynamics damping="0.1"/>
            </joint>
        
            <link name="proximal_RF">
                <origin xyz="0 0 0" rpy="0 0 0"/>

                <inertial>
                    <origin xyz="0 0 0.0225" rpy="0 0 0"/>
                    <mass value="0.03"/>
                    <inertia 
                        ixx="9.8e-06" 
                        ixy="0" 
                        ixz="0" 
                        iyy="1.0e-05" 
                        iyz="0" 
                        izz="1.8e-06"
                    />
                </inertial>

                <visual>
                    <origin xyz="0 0 0" rpy="0 0 0"/>
                    <geometry name="visual_knuckle_link">
                        <mesh filename="/meshes/F3.dae" scale="0.001 0.001 0.001"/>
                    </geometry>
                    <material name = "proximal_RF_color">
                        <color rgba="0.7 1 1 1"/>
                    </material>
                </visual>

                <collision>
                    <origin xyz="0 0 0" rpy="0 0 0"/>
                    <geometry name="collision_knuckle_link">
                        <mesh filename="/meshes/F3_c.dae" scale="0.001 0.001 0.001"/>
                    </geometry>
                    <material name="Grey"/>
                </collision>
            </link>

            <joint name="J3_RF" type="revolute">
                <parent link="knuckle_RF"/>
                <child link ="proximal_RF"/>

                <origin xyz="0 0 0" rpy="0 0 0"/>
                <axis xyz="1 0 0"/>
                <limit  effort="2.0" 
                        lower="0" 
                        upper="1.5708" 
                        velocity="2.0" />
                <dynamics damping="0.1"/>
            </joint>
        
            <link name="middle_RF">
                <origin xyz="0 0 0" rpy="0 0 0"/>

                <inertial>
                    <origin xyz="0 0 0.0125" rpy="0 0 0"/>
                    <mass value="0.017"/>
                    <inertia 
                        ixx="2.6e-06" 
                        ixy="0" 
                        ixz="0" 
                        iyy="2.7e-06" 
                        iyz="0" 
                        izz="8.7e-07"
                    />
                </inertial>

                <visual>
                    <origin xyz="0 0 0" rpy="0 0 0"/>
                    <geometry name="visual_knuckle_link">
                        <mesh filename="/meshes/F2.dae" scale="0.001 0.001 0.001"/>
                    </geometry>
                    <material name = "middle_RF_color">
                        <color rgba="0.8 0.3 0.6 1"/>
                    </material>
                </visual>

                <collision>
                    <origin xyz="0 0 0" rpy="0 0 0"/>
                    <geometry name="collision_knuckle_link">
                        <mesh filename="/meshes/F2_c.dae" scale="0.001 0.001 0.001"/>
                    </geometry>
                    <material name="Grey"/>
                </collision>
            </link>

            <joint name="J2_RF" type="revolute">
                <parent link="proximal_RF"/>
                <child link ="middle_RF"/>

                <origin xyz="0 0 0.045" rpy="0 0 0"/>
                <axis xyz="1 0 0"/>
                <limit  effort="2.0" 
                        lower="0" 
                        upper="1.5708" 
                        velocity="2.0" />
                <dynamics damping="0.1"/>
            </joint>
        
            <link name="distal_RF">
                <origin xyz="0 0 0" rpy="0 0 0"/>

                <inertial>
                    <origin xyz="0 0 0.012" rpy="0 0 0"/>
                    <mass value="0.012"/>
                    <inertia 
                        ixx="9.4e-07" 
                        ixy="0" 
                        ixz="0" 
                        iyy="1.1e-06" 
                        iyz="0" 
                        izz="5.3e-07"
                    />
                </inertial>

                <visual>
                    <origin xyz="0 0 0" rpy="0 0 0"/>
                    <geometry name="visual_knuckle_link">
                        <mesh filename="/meshes/digit.STL" scale="1 1 1"/>
                    </geometry>
                    <material name = "distal_RF_color">
                        <color rgba="1 1 1 1"/>
                    </material>
                </visual>

                <collision>
                    <origin xyz="0 0 0" rpy="0 0 0"/>
                    <geometry name="collision_knuckle_link">
                        <mesh filename="/meshes/digit.STL" scale="1 1 1"/>
                    </geometry>
                    <material name="Grey"/>
                </collision>
            </link>

            <joint name="J1_RF" type="revolute">
                <parent link="middle_RF"/>
                <child link ="distal_RF"/>

                <origin xyz="0 0 0.025" rpy="0 0 -1.57"/>
                <axis xyz="0 1 0"/>
                <limit  effort="2.0" 
                        lower="0" 
                        upper="1.5708" 
                        velocity="2.0" />
                <dynamics damping="0.1"/>
            </joint>
        
    
    <!-- thumb  -->

    

        
            <link name="thbase">
                <origin xyz="0 0 0" rpy="0 0 0"/>

                <inertial>
                    <origin xyz="0 0 0" rpy="0 0 0"/>
                    <mass value="0.01"/>
                    <inertia 
                        ixx="1.6e-07" 
                        ixy="0" 
                        ixz="0" 
                        iyy="1.6e-07" 
                        iyz="0" 
                        izz="1.6e-07"
                    />
                </inertial>

                <visual>
                    <origin xyz="0 0 0" rpy="0 0 0"/>
                    
                    
                        
                        <geometry name="lh_thhub_visual">
                            <box size="0.001 0.001 0.001"/>
                        </geometry>

                    

                     <material name = "thbase_color">
                            <color rgba="0 0 0 1"/>
                    </material>
                </visual>

                <collision>
                    <origin xyz="0 0 0" rpy="0 0 0"/>
                     
                     
                        
                        <geometry name="lh_thhub_collision">
                            <box size="0.001 0.001 0.001"/>
                        </geometry>

                    

                    <material name="Grey"/>
                </collision>
            </link>

            <joint name="THJ5" type="revolute">
                <parent link="palm"/>
                <child link ="thbase"/>

                <origin xyz="-0.034 -0.0085 0.029" rpy="0 0.785398163397 3.14159265359"/>
                <axis xyz="0 0 0.541675"/>
                
                

                    <limit  effort="5.0" 
                            lower="-1.0472" 
                            upper="1.0472" 
                            velocity="4.0" />
                    <dynamics damping="0.2"/>

                

            </joint>
        

        
            <link name="thproximal">
                <origin xyz="0 0 0" rpy="0 0 0"/>

                <inertial>
                    <origin xyz="0 0 0.021111" rpy="0 0 0"/>
                    <mass value="0.04"/>
                    <inertia 
                        ixx="1.36e-05" 
                        ixy="0" 
                        ixz="0" 
                        iyy="1.36e-05" 
                        iyz="0" 
                        izz="3.13e-06"
                    />
                </inertial>

                <visual>
                    <origin xyz="0 0 0" rpy="0 0 0"/>
                    
                    
                        
                        <geometry name="collision_knuckle_link">
                            <mesh filename="/meshes/TH3_z.dae" scale="0.001 0.001 0.001"/>
                        </geometry>
                       
             
                    

                     <material name = "thproximal_color">
                            <color rgba="0.8 0.8 0.8 1"/>
                    </material>
                </visual>

                <collision>
                    <origin xyz="0 0 0" rpy="0 0 0"/>
                     
                     
                        
                        <geometry name="collision_knuckle_link">
                            <mesh filename="/meshes/TH3_z_c.dae" scale="0.001 0.001 0.001"/>
                        </geometry>
                       
                    

                    <material name="Grey"/>
                </collision>
            </link>

            <joint name="THJ4" type="revolute">
                <parent link="thbase"/>
                <child link ="thproximal"/>

                <origin xyz="0 0 0" rpy="0 0 0"/>
                <axis xyz="-0.707107 -0.454519 -0.541675"/>
                
                

                    <limit  effort="3.0" 
                            lower="0" 
                            upper="1.22173" 
                            velocity="4.0" />
                    <dynamics damping="0.2"/>

                

            </joint>
        

        
            <link name="thhub">
                <origin xyz="0 0 0" rpy="0 0 0"/>

                <inertial>
                    <origin xyz="0 0 0" rpy="0 0 0"/>
                    <mass value="0.005"/>
                    <inertia 
                        ixx="1.0e-06" 
                        ixy="0" 
                        ixz="0" 
                        iyy="1.0e-06" 
                        iyz="0" 
                        izz="3.0e-07"
                    />
                </inertial>

                <visual>
                    <origin xyz="0 0 0" rpy="0 0 0"/>
                    
                    
                        
                        <geometry name="lh_thhub_visual">
                            <box size="0.001 0.001 0.001"/>
                        </geometry>

                    

                     <material name = "thhub_color">
                            <color rgba="0 0 0 1"/>
                    </material>
                </visual>

                <collision>
                    <origin xyz="0 0 0" rpy="0 0 0"/>
                     
                     
                        
                        <geometry name="lh_thhub_collision">
                            <box size="0.001 0.001 0.001"/>
                        </geometry>

                    

                    <material name="Grey"/>
                </collision>
            </link>

            <joint name="THJ3" type="fixed">
                <parent link="thproximal"/>
                <child link ="thhub"/>

                <origin xyz="0 0 0.038" rpy="0 0 0.038"/>
                <axis xyz="1 0 0"/>
                
                

            </joint>
        

        
            <link name="thmiddle">
                <origin xyz="0 0 0" rpy="0 0 0"/>

                <inertial>
                    <origin xyz="0 0 0.16" rpy="0 0 0"/>
                    <mass value="0.02"/>
                    <inertia 
                        ixx="5.1e-06" 
                        ixy="0" 
                        ixz="0" 
                        iyy="5.1e-06" 
                        iyz="0" 
                        izz="1.21e-06"
                    />
                </inertial>

                <visual>
                    <origin xyz="0 0 0" rpy="0 0 0"/>
                    
                    
                        
                        <geometry name="collision_knuckle_link">
                            <mesh filename="/meshes/TH2_z.dae" scale="0.001 0.001 0.001"/>
                        </geometry>
                       
             
                    

                     <material name = "thmiddle_color">
                            <color rgba="0.8 0.7 0.6 1"/>
                    </material>
                </visual>

                <collision>
                    <origin xyz="0 0 0" rpy="0 0 0"/>
                     
                     
                        
                        <geometry name="collision_knuckle_link">
                            <mesh filename="/meshes/TH2_z_c.dae" scale="0.001 0.001 0.001"/>
                        </geometry>
                       
                    

                    <material name="Grey"/>
                </collision>
            </link>

            <joint name="THJ2" type="revolute">
                <parent link="thhub"/>
                <child link ="thmiddle"/>

                <origin xyz="0 0 0" rpy="0 0 0"/>
                <axis xyz="0 -0.766044 0.642788"/>
                
                

                    <limit  effort="2.0" 
                            lower="-0.698132" 
                            upper="0.698132" 
                            velocity="2.0" />
                    <dynamics damping="0.1"/>

                

            </joint>
        

        
            <link name="thdistal">
                <origin xyz="0 0 0" rpy="0 0 0"/>

                <inertial>
                    <origin xyz="0 0 0.014559" rpy="0 0 0"/>
                    <mass value="0.016"/>
                    <inertia 
                        ixx="2.1e-06" 
                        ixy="0" 
                        ixz="0" 
                        iyy="2.2e-06" 
                        iyz="0" 
                        izz="1.0e-06"
                    />
                </inertial>

                <visual>
                    <origin xyz="0 0 0" rpy="0 0 0"/>
                    
                    
                        
                        <geometry name="collision_knuckle_link">
                            <mesh filename="/meshes/digit.STL" scale="1 1 1"/>
                        </geometry>
                       
             
                    

                     <material name = "thdistal_color">
                            <color rgba="0.9 0 0.2 1"/>
                    </material>
                </visual>

                <collision>
                    <origin xyz="0 0 0" rpy="0 0 0"/>
                     
                     
                        
                        <geometry name="collision_knuckle_link">
                            <mesh filename="/meshes/digit.STL" scale="1 1 1"/>
                        </geometry>
                       
                    

                    <material name="Grey"/>
                </collision>
            </link>

            <joint name="THJ1" type="revolute">
                <parent link="thmiddle"/>
                <child link ="thdistal"/>

                <origin xyz="0 0 0.032" rpy="0 0 3.14"/>
                <axis xyz="0 1 0"/>
                
                

                    <limit  effort="1.0" 
                            lower="0" 
                            upper="1.5708" 
                            velocity="4.0" />
                    <dynamics damping="0.2"/>

                

            </joint>
        
    



</robot>